<?xml version="1.0" ?>
<robot name="srm_urdf" xmlns:xacro="http://www.ros.org/wiki/xacro">

<xacro:include filename="$(find srm_urdf_description)/urdf/materials.xacro" />
<xacro:include filename="$(find srm_urdf_description)/urdf/srm_urdf.trans" />
<xacro:include filename="$(find srm_urdf_description)/urdf/srm_urdf.gazebo" />
<link name="base_link">
  <inertial>
    <origin xyz="0.10568381868504272 -0.20590256745891375 0.006515567856673277" rpy="0 0 0"/>
    <mass value="6.7691812168031795"/>
    <inertia ixx="0.024906" iyy="0.072898" izz="0.065241" ixy="-0.011564" iyz="0.00098" ixz="0.006015"/>
  </inertial>
  <visual>
    <origin xyz="0 0 0" rpy="0 0 0"/>
    <geometry>
      <mesh filename="package://srm_urdf_description/meshes/base_link.stl" scale="0.001 0.001 0.001"/>
    </geometry>
    <material name="silver"/>
  </visual>
  <collision>
    <origin xyz="0 0 0" rpy="0 0 0"/>
    <geometry>
      <mesh filename="package://srm_urdf_description/meshes/base_link.stl" scale="0.001 0.001 0.001"/>
    </geometry>
  </collision>
</link>

<link name="link_0_1">
  <inertial>
    <origin xyz="0.0057414043556299615 0.04202043071093817 0.0017004351472542944" rpy="0 0 0"/>
    <mass value="7.354010683693323"/>
    <inertia ixx="0.013079" iyy="0.022247" izz="0.016572" ixy="0.000187" iyz="-0.000312" ixz="-8.9e-05"/>
  </inertial>
  <visual>
    <origin xyz="-0.047 0.205 -0.0005" rpy="0 0 0"/>
    <geometry>
      <mesh filename="package://srm_urdf_description/meshes/link_0_1.stl" scale="0.001 0.001 0.001"/>
    </geometry>
    <material name="silver"/>
  </visual>
  <collision>
    <origin xyz="-0.047 0.205 -0.0005" rpy="0 0 0"/>
    <geometry>
      <mesh filename="package://srm_urdf_description/meshes/link_0_1.stl" scale="0.001 0.001 0.001"/>
    </geometry>
  </collision>
</link>

<link name="link_1_1">
  <inertial>
    <origin xyz="0.0007062283060149213 0.03249199908132147 -0.014219526363014127" rpy="0 0 0"/>
    <mass value="2.8137687577683543"/>
    <inertia ixx="0.006245" iyy="0.003148" izz="0.00427" ixy="-4.3e-05" iyz="-0.000882" ixz="-2.9e-05"/>
  </inertial>
  <visual>
    <origin xyz="-0.0 0.11 -0.01275" rpy="0 0 0"/>
    <geometry>
      <mesh filename="package://srm_urdf_description/meshes/link_1_1.stl" scale="0.001 0.001 0.001"/>
    </geometry>
    <material name="silver"/>
  </visual>
  <collision>
    <origin xyz="-0.0 0.11 -0.01275" rpy="0 0 0"/>
    <geometry>
      <mesh filename="package://srm_urdf_description/meshes/link_1_1.stl" scale="0.001 0.001 0.001"/>
    </geometry>
  </collision>
</link>

<link name="link_2_1">
  <inertial>
    <origin xyz="0.005655179920818344 -0.0006639946683364204 0.030795357983687772" rpy="0 0 0"/>
    <mass value="1.0334607047767101"/>
    <inertia ixx="0.000804" iyy="0.000441" izz="0.00064" ixy="1e-06" iyz="-2e-06" ixz="3.7e-05"/>
  </inertial>
  <visual>
    <origin xyz="-0.0 0.0 0.02275" rpy="0 0 0"/>
    <geometry>
      <mesh filename="package://srm_urdf_description/meshes/link_2_1.stl" scale="0.001 0.001 0.001"/>
    </geometry>
    <material name="silver"/>
  </visual>
  <collision>
    <origin xyz="-0.0 0.0 0.02275" rpy="0 0 0"/>
    <geometry>
      <mesh filename="package://srm_urdf_description/meshes/link_2_1.stl" scale="0.001 0.001 0.001"/>
    </geometry>
  </collision>
</link>

<link name="link_3_1">
  <inertial>
    <origin xyz="-0.04727197567079266 7.69410115421254e-06 -0.0003577061243398847" rpy="0 0 0"/>
    <mass value="0.8514022633262588"/>
    <inertia ixx="0.000228" iyy="0.000894" izz="0.000818" ixy="-0.0" iyz="-0.0" ixz="1.1e-05"/>
  </inertial>
  <visual>
    <origin xyz="0.009 -0.026 -0.00025" rpy="0 0 0"/>
    <geometry>
      <mesh filename="package://srm_urdf_description/meshes/link_3_1.stl" scale="0.001 0.001 0.001"/>
    </geometry>
    <material name="silver"/>
  </visual>
  <collision>
    <origin xyz="0.009 -0.026 -0.00025" rpy="0 0 0"/>
    <geometry>
      <mesh filename="package://srm_urdf_description/meshes/link_3_1.stl" scale="0.001 0.001 0.001"/>
    </geometry>
  </collision>
</link>

<link name="link_4_1">
  <inertial>
    <origin xyz="0.0003315465873139356 -0.0009813987579149058 -0.021611662520797378" rpy="0 0 0"/>
    <mass value="0.24817393543220678"/>
    <inertia ixx="5.5e-05" iyy="5.4e-05" izz="4.2e-05" ixy="-0.0" iyz="-1e-06" ixz="0.0"/>
  </inertial>
  <visual>
    <origin xyz="0.116 -0.026 -0.02525" rpy="0 0 0"/>
    <geometry>
      <mesh filename="package://srm_urdf_description/meshes/link_4_1.stl" scale="0.001 0.001 0.001"/>
    </geometry>
    <material name="silver"/>
  </visual>
  <collision>
    <origin xyz="0.116 -0.026 -0.02525" rpy="0 0 0"/>
    <geometry>
      <mesh filename="package://srm_urdf_description/meshes/link_4_1.stl" scale="0.001 0.001 0.001"/>
    </geometry>
  </collision>
</link>

<link name="link_5_1">
  <inertial>
    <origin xyz="-1.3707104784543844e-08 0.0011488829522393927 -0.000522684591547189" rpy="0 0 0"/>
    <mass value="0.012501675944322615"/>
    <inertia ixx="0.0" iyy="0.0" izz="0.0" ixy="0.0" iyz="0.0" ixz="-0.0"/>
  </inertial>
  <visual>
    <origin xyz="0.115952 -0.001 -0.00125" rpy="0 0 0"/>
    <geometry>
      <mesh filename="package://srm_urdf_description/meshes/link_5_1.stl" scale="0.001 0.001 0.001"/>
    </geometry>
    <material name="silver"/>
  </visual>
  <collision>
    <origin xyz="0.115952 -0.001 -0.00125" rpy="0 0 0"/>
    <geometry>
      <mesh filename="package://srm_urdf_description/meshes/link_5_1.stl" scale="0.001 0.001 0.001"/>
    </geometry>
  </collision>
</link>

<joint name="joint_0" type="revolute">
  <origin xyz="0.047 -0.205 0.0005" rpy="0 0 0"/>
  <parent link="base_link"/>
  <child link="link_0_1"/>
  <axis xyz="0.0 1.0 0.0"/>
  <limit upper="1.396263" lower="-1.396263" effort="100" velocity="100"/>
</joint>

<joint name="joint_1" type="revolute">
  <origin xyz="-0.047 0.095 0.01225" rpy="0 0 0"/>
  <parent link="link_0_1"/>
  <child link="link_1_1"/>
  <axis xyz="-0.0 0.0 -1.0"/>
  <limit upper="1.396263" lower="-2.530727" effort="100" velocity="100"/>
</joint>

<joint name="joint_2" type="revolute">
  <origin xyz="0.0 0.11 -0.0355" rpy="0 0 0"/>
  <parent link="link_1_1"/>
  <child link="link_2_1"/>
  <axis xyz="-0.0 0.0 -1.0"/>
  <limit upper="1.047198" lower="-1.047198" effort="100" velocity="100"/>
</joint>

<joint name="joint_3" type="revolute">
  <origin xyz="-0.009 0.026 0.023" rpy="0 0 0"/>
  <parent link="link_2_1"/>
  <child link="link_3_1"/>
  <axis xyz="1.0 -0.0 -0.0"/>
  <limit upper="3.141593" lower="-3.141593" effort="100" velocity="100"/>
</joint>

<joint name="joint_4" type="revolute">
  <origin xyz="-0.107 0.0 0.025" rpy="0 0 0"/>
  <parent link="link_3_1"/>
  <child link="link_4_1"/>
  <axis xyz="-0.0 -0.0 1.0"/>
  <limit upper="0.436332" lower="-3.665191" effort="100" velocity="100"/>
</joint>

<joint name="joint_5" type="revolute">
  <origin xyz="4.8e-05 -0.025 -0.024" rpy="0 0 0"/>
  <parent link="link_4_1"/>
  <child link="link_5_1"/>
  <axis xyz="0.0 1.0 0.0"/>
  <limit upper="3.141593" lower="-3.141593" effort="100" velocity="100"/>
</joint>

</robot>
